Workbook

Sheet Sheet1
A1: Serial Number | B1: Device Type | C1: Airtel | D1: OS | E1: Model | F1: Mac Address | G1: Wifi Macaddress | H1: Auuid | I1: Staff Type | J1: Staff Name | K1: Department | L1: Hostname | M1: Allocated Date | N1: Location | O1: Remark | P1: Warranty Expiry Date
A2: 5CD3314F8M | B2: Laptop | C2: Airtel | E2: HP ProBook 440 G10 | H2: 13404947 | J2: Simon Ng'ang'a Waweru | L2: KE-13404947-WL
A3: PW0BRE3A | B3: Laptop | C3: Airtel | E3: ThinkBook 14 G6 IRL | H3: 13406568 | J3: Peter Kagechu | L3: KE-13406568-WL
A4: 5CD32961SC | B4: Laptop | C4: Airtel | E4: HP ProBook 440 G10 | H4: 1316480 | J4: Catherine Wangari Kamau | L4: KE-1316480L-WL
A5: PW0BS2L0 | B5: Laptop | C5: Airtel | E5: ThinkBook 14 G6 IRL | H5: 13406616 | J5: Dan Kyallo | L5: KE-13406616-WL
A6: 5CD9519LPY | B6: Laptop | C6: Airtel | E6: HP ProBook 430 G6 | H6: 2356272 | J6: Eunice Ndolo | L6: 2356272L
A7: 5CG7010M66 | B7: Laptop | C7: Airtel | E7: HP EliteBook 840G3 | H7: 23188761 | J7: Mr. Brayn Muhanji | L7: KE-23188761-WL
A8: PW0D4KJ8 | B8: Laptop | C8: Airtel | E8: ThinkBook 14 G6 IRL | H8: 13403306 | J8: Stephen Charles | L8: KE-13403306-WL
A9: 5CD3314F1V | B9: Laptop | C9: Airtel | E9: HP ProBook 440 G10 | H9: 13209008 | J9: Enock Cheruiyot | L9: 13209008L
A10: PW0EYYQ5 | B10: Laptop | C10: Airtel | E10: ThinkBook 14 G6 IRL | H10: 1322457 | J10: #N/A | L10: KE-1322457-WL
A11: 5CD118CSH4 | B11: Laptop | C11: Airtel | E11: HP Spectre x360 | H11: #N/A | J11: #N/A | L11: KE-13400832-WL
A12: 5CD108G73D | B12: Laptop | C12: Airtel | E12: HP ProBook 430 G8 | H12: 1304329 | J12: Mary Waweru | L12: 1304329L1
A13: 5CD225L14S | B13: Laptop | C13: Airtel | E13: Hp Probook 430 G8 | H13: 13403304 | J13: Peter Mwangi | L13: KE-13403304-WL
A14: 5CD225L13S | B14: Laptop | C14: Airtel | E14: Hp Probook 430 G8 | H14: 132093392 | J14: Adams Nandasaba Wanyonyi | L14: 13209339L2
A15: 5CD3314F6R | B15: Laptop | C15: Airtel | E15: HP ProBook 440 G10 | H15: 13405835 | J15: Faith Wambui Bundi | L15: KE-13405835-WL
A16: 5CD010D58J | B16: Laptop | C16: Airtel | E16: HP ProBook 430 G6 | H16: 23209090 | J16: Mr. Richard Njaria | L16: KE-23209090-WL
A17: PW0D4KH5 | B17: Laptop | C17: Airtel | E17: ThinkBook 14 G6 IRL | H17: 1304269 | J17: Nick Kariuki Murage | L17: KE-1304269-WL
A18: PW0BRE37 | B18: Laptop | C18: Airtel | E18: ThinkBook 14 G6 IRL | H18: 13207110 | J18: Catherine Wairimu Wanjohi | L18: KE-13207110-WL
A19: 5CD3314F8X | B19: Laptop | C19: Airtel | E19: HP ProBook 440 G10 | H19: 2388080 | J19: Mr. Kennedy Musembi | L19: KE-2388080-WL
A20: 5CD225L149 | B20: Laptop | C20: Airtel | E20: HP ProBook 430 G8 | H20: 2356569 | J20: Mr. JOSEPH MUNGAI | L20: KE-2356569-WL
A21: 5CD3314F3Y | B21: Laptop | C21: Airtel | E21: HP ProBook 440 G10 | H21: 13402750 | J21: Moses Mukhwana | L21: KE-13402750-WL
A22: 5CD120S0HW | B22: Laptop | C22: Airtel | E22: Hp Probook 430 G8 | H22: 23148600 | J22: Ms. Cytlin Ochieng | L22: KE-23148600-WL
A23: PW0D4KHB | B23: Laptop | C23: Airtel | E23: ThinkBook 14 G6 IRL | H23: 23128304 | J23: Rebecca Wanjiru | L23: KE-23128304-WL
... A73: 5CD108G75J | B73: Laptop | C73: Airtel | E73: HP ProBook 430 G8 | H73: 13209113 | J73: Lilian Monchari Mogire | L73: KE-13209113-WL
A74: #N/A | B74: Laptop | C74: Airtel | E74: #N/A | H74: #N/A | J74: #N/A | L74: KE-23135932-WL
A75: 5CD1013RW7 | B75: Laptop | C75: Airtel | E75: HP ProBook 430 G8 | H75: 23215300 | J75: Mr. Maxwel Maingi | L75: KE--23215300-WL
A76: MJ0D9LPZ | B76: Laptop | C76: Airtel | E76: Lenovo T490s | H76: 23154674 | J76: Mr. Simon Musembi | L76: KE-23154674--WL
A77: PF5S4Y8G | B77: Laptop | C77: Airtel | E77: Lenovo T14s | H77: 138205 | J77: Shailendra Singh | L77: KE-138205-WL1
A78: PW0EC3CG | B78: Laptop | C78: Airtel | E78: ThinkBook 14 G6 IRL | H78: 13401112 | J78: #N/A | L78: KE-13401112-WL1
A79: 5CD3314F9Y | B79: Laptop | C79: Airtel | E79: HP ProBook 440 G10 | H79: 1304267 | J79: Charles Mutembei | L79: KE-1304267-WL
A80: PC1ML3XA | B80: Desktop | C80: Airtel | E80: Lenovo V530 | H80: 23218317 | J80: Ms. Sheila Wamahiu | L80: KE-23218317-WL
A81: PC1MKSJR | B81: Desktop | C81: Airtel | E81: Lenovo V530 | H81: 23189610 | J81: Mr. Carlos Mwanthi | L81: KE-23189610-WL
A82: 5CD3314F75 | B82: Laptop | C82: Airtel | E82: HP ProBook 440 G10 | H82: 23134662 | J82: Wycliff Morara | L82: KE-23134662-WL
A83: 5CD1013RZ9 | B83: Laptop | C83: Airtel | E83: HP ProBook 430 G8 | H83: 23188037 | J83: Ms. Patience Chepchirchir | L83: KE-23188037-WL
A84: 5CD9519LQ7 | B84: Laptop | C84: Airtel | E84: HP ProBook 430 G6 | H84: 2388243 | J84: Ms. Linda Jeptoo | L84: KE-2388243-WL
A85: MJ0D9L4N | B85: Laptop | C85: Airtel | E85: Lenovo T490s | H85: 23189029 | J85: Mr. Samuel Nduati | L85: KE-23189029-WL
A86: PW0BS2KX | B86: Laptop | C86: Airtel | E86: ThinkBook 14 G6 IRL | H86: 2368897 | J86: Ms. Charity Ajaa | L86: KE-2368897-WL
A87: 5CD108G76J | B87: Laptop | C87: Airtel | E87: HP ProBook 430 G8 | H87: 1300948 | J87: Elizabeth Kigotho | L87: KE-1300948-WL
A88: 5CD010D58G | B88: Laptop | C88: Airtel | E88: HP ProBook 430 G6 | H88: 23217925 | J88: Ms. Grace Musyimi | L88: KE-23217925-WL
A89: R90RA31C | B89: Laptop | C89: Airtel | E89: #N/A | H89: #N/A | J89: #N/A | L89: KE-2354620-WL
...

Sheet All Offroll Employess
A1: Associate Number | C1: Full Name | D1: Person Type | E1: Organization | F1: Date of Joining | G1: Supervisor Number | H1: Supervisor Name | I1: Email Address | J1: Phone Number | K1: PARTNER_CATEGORY | L1: PARTNER_NAME | M1: National_ID_Type | N1: National_ID_Num
A2: 2300031 | B2: =_xlfn.XLOOKUP(A2,'[2]Crowdstrike report'!$S:$S,'[2]Crowdstrike report'!$A:$A,0) -> 0 | C2: Mr. Habert KHISA | D2: Contingent Worker | E2: Airtel Kenya | F2: 41191 | G2: 401256 | H2: Chengole, Mr. Ian Walingo | I2: a_Herbert.Khisa@ke.airtel.com | J2: 254738567729 | K2: Contingent Worker | L2: Bollore
A3: 2300032 | B3: =_xlfn.XLOOKUP(A3,'[2]Crowdstrike report'!$S:$S,'[2]Crowdstrike report'!$A:$A,0) -> KE-2300032-WD | C3: Mr. Peter MWILU | D3: Contingent Worker | E3: Airtel Kenya | F3: 41191 | G3: 401256 | H3: Chengole, Mr. Ian Walingo | I3: a_Peter.Mwilu@ke.airtel.com | J3: 254733336394 | K3: Contingent Worker | L3: Bollore
A4: 2300034 | B4: =_xlfn.XLOOKUP(A4,'[2]Crowdstrike report'!$S:$S,'[2]Crowdstrike report'!$A:$A,0) -> 0 | C4: Jeniffer MUHORO | D4: Contingent Worker | E4: Airtel Kenya | F4: 41191 | G4: 401256 | H4: Chengole, Mr. Ian Walingo | I4: a_jeniffer.Muhoro@ke.airtel.com | J4: 254731004154 | K4: Contingent Worker | L4: Bollore
A5: 2300117 | B5: =_xlfn.XLOOKUP(A5,'[2]Crowdstrike report'!$S:$S,'[2]Crowdstrike report'!$A:$A,0) -> 0 | C5: Christine Ogalo | D5: Contingent Worker | E5: Airtel Kenya | F5: 41449 | G5: 1304512 | H5: Kihiu, Mr. Duncan Mumenya | I5: a_Christine.Ogalo@ke.airtel.com | J5: 254738217321 | K5: Offrole | L5: Sheer Logic Management Consultants
A6: 2304321 | B6: =_xlfn.XLOOKUP(A6,'[2]Crowdstrike report'!$S:$S,'[2]Crowdstrike report'!$A:$A,0) -> KE-2304321-WD | C6: Mr. SAMUEL MATHEKA | D6: Contingent Worker | E6: Airtel Kenya | F6: 42031 | G6: 401256 | H6: Chengole, Mr. Ian Walingo | I6: a_samuel.matheka@ke.airtel.com | J6: 254738567180 | K6: Contingent Worker | L6: Bollore
A7: 2304952 | B7: =_xlfn.XLOOKUP(A7,'[2]Crowdstrike report'!$S:$S,'[2]Crowdstrike report'!$A:$A,0) -> 0 | C7: Mr. Moses Mburu | D7: Contingent Worker | E7: Airtel Kenya | F7: 42065 | G7: 2323054 | H7: Kiama, John | I7: a_Moses.Mburu@ke.airtel.com | J7: 254735939810 | K7: Contingent Worker | L7: IBM-Maraison
A8: 23100021 | B8: =_xlfn.XLOOKUP(A8,'[2]Crowdstrike report'!$S:$S,'[2]Crowdstrike report'!$A:$A,0) -> 0 | C8: Ms. Jane Kariuki | D8: Contingent Worker | E8: Airtel Kenya | F8: 43907 | G8: 1319123 | H8: Nyaga, Mr. Henry Mwangi | I8: jane.kariuki@zte.com.cn | J8: 254733889737 | K8: Contingent Worker | L8: ZTE
A9: 23100159 | B9: =_xlfn.XLOOKUP(A9,'[2]Crowdstrike report'!$S:$S,'[2]Crowdstrike report'!$A:$A,0) -> KE-23100159-WL | C9: Mr. Geofrey Otieno | D9: Contingent Worker | E9: Airtel Kenya | F9: 43910 | G9: 1303431 | H9: Abuga, Mr. Jared Masi | I9: a_geofrey.otieno@ke.airtel.com | J9: 254731737388 | K9: Contingent Worker | L9: Airtel Offrole
A10: 23100661 | B10: =_xlfn.XLOOKUP(A10,'[2]Crowdstrike report'!$S:$S,'[2]Crowdstrike report'!$A:$A,0) -> KE-23100661-WL | C10: Mr. BONFACE OUMA | D10: Contingent Worker | E10: Airtel Kenya | F10: 43920 | G10: 404583 | H10: Kariuki, Mr. Fredrick Wachira | I10: a_bonface.ouma@ke.airtel.com | J10: 254781364747 | K10: Offrole | L10: Sheer Logic Management Consultants
A11: 23100662 | B11: =_xlfn.XLOOKUP(A11,'[2]Crowdstrike report'!$S:$S,'[2]Crowdstrike report'!$A:$A,0) -> KE-23100662-WD | C11: Mr. WALTER KADURENGE | D11: Contingent Worker | E11: Airtel Kenya | F11: 43920 | G11: 404583 | H11: Kariuki, Mr. Fredrick Wachira | I11: a_walter.kadurenge@ke.airtel.com | J11: 254789792029 | K11: Contingent Worker | L11: Bollore Logistics
A12: 23101437 | B12: =_xlfn.XLOOKUP(A12,'[2]Crowdstrike report'!$S:$S,'[2]Crowdstrike report'!$A:$A,0) -> 0 | C12: Mr. Sanjeevkumar Shanmugavadivel | D12: Contingent Worker | E12: Airtel Kenya | F12: 43929 | G12: 2395298 | H12: SINGH, Mr. DUSHYANT KUMAR | I12: sanjeevkumar.shanmugavadivel.ext@nokia.com | J12: 919865516899 | K12: Contingent Worker | L12: Nokia
A13: 23101443 | B13: =_xlfn.XLOOKUP(A13,'[2]Crowdstrike report'!$S:$S,'[2]Crowdstrike report'!$A:$A,0) -> 0 | C13: Mr. Srinivasan Natarajan | D13: Contingent Worker | E13: Airtel Kenya | F13: 43929 | G13: 2395298 | H13: SINGH, Mr. DUSHYANT KUMAR | I13: srinivasan.natarajan.ext@nokia.com | J13: 919629271103 | K13: Contingent Worker | L13: Nokia
... A107: 23115184 | B107: =_xlfn.XLOOKUP(A107,'[2]Crowdstrike report'!$S:$S,'[2]Crowdstrike report'!$A:$A,0) -> KE-23115184-WD | C107: Mr. Januaries Musembi | D107: Contingent Worker | E107: Airtel Kenya | F107: 43836 | G107: 23102016 | H107: Agarwal, Mr. Prashant Kumar | I107: januaries.musembi.ext@nokia.com | J107: 254706305211 | K107: Contingent Worker | L107: Innovis - Nokia
A108: 23115407 | B108: =_xlfn.XLOOKUP(A108,'[2]Crowdstrike report'!$S:$S,'[2]Crowdstrike report'!$A:$A,0) -> 0 | C108: Mr. Vincent Ngala | D108: Contingent Worker | E108: Airtel Kenya | F108: 44208 | I108: vincent.ngala.ext@nokia.com | J108: 254737593902 | K108: Contingent Worker | L108: NOKIA
A109: 23115601 | B109: =_xlfn.XLOOKUP(A109,'[2]Crowdstrike report'!$S:$S,'[2]Crowdstrike report'!$A:$A,0) -> 0 | C109: Ms. Celine Otieno | D109: Contingent Worker | E109: Airtel Kenya | F109: 44216 | G109: 404881 | H109: Atieno, Ms. Verolyne | I109: a_celine.otieno@ke.airtel.com | J109: 254787770147 | K109: Offrole | L109: Sheer Logic Management Consultants
A110: 23115649 | B110: =_xlfn.XLOOKUP(A110,'[2]Crowdstrike report'!$S:$S,'[2]Crowdstrike report'!$A:$A,0) -> 0 | C110: Ms. Hellen Kangara | D110: Contingent Worker | E110: Airtel Kenya | F110: 44217 | G110: 406738 | H110: Wairindi, Ms. Jacklyne Wambui | I110: a_hellen.kangara@ke.airtel.com | J110: 254734896012 | K110: Offrole | L110: Sheer Logic Management Consultants
A111: 23116273 | B111: =_xlfn.XLOOKUP(A111,'[2]Crowdstrike report'!$S:$S,'[2]Crowdstrike report'!$A:$A,0) -> 0 | C111: Mr. Shadrack Emachar | D111: Contingent Worker | E111: Airtel Kenya | F111: 44230 | G111: 404288 | H111: Karaimu, Mr. Daniel Wanyika | I111: a_shadrack.emachar@ke.airtel.com | J111: 254732794213 | K111: Offrole | L111: Sheer Logic Management Consultants
A112: 23116425 | B112: =_xlfn.XLOOKUP(A112,'[2]Crowdstrike report'!$S:$S,'[2]Crowdstrike report'!$A:$A,0) -> KE-23116425-WL | C112: Mr. Bob Suri | D112: Contingent Worker | E112: Airtel Kenya | F112: 44232 | G112: 1300135 | H112: Mbogori, Ms. Freda K. | I112: a_bob.suri@ke.airtel.com | J112: 254753920723 | K112: Offrole | L112: Sheer Logic Management Consultants
A113: 23119279 | B113: =_xlfn.XLOOKUP(A113,'[2]Crowdstrike report'!$S:$S,'[2]Crowdstrike report'!$A:$A,0) -> KE-23119279-WD | C113: Ms. Eunice Omuhaka | D113: Contingent Worker | E113: Airtel Kenya | F113: 44246 | G113: 401066 | H113: Namayi, Miss Florence Akinyi | I113: a_eunice.omuhaka@ke.airtel.com | J113: 254781992763 | K113: Offrole | L113: Sheer Logic Management Consultants
A114: 23119290 | B114: =_xlfn.XLOOKUP(A114,'[2]Crowdstrike report'!$S:$S,'[2]Crowdstrike report'!$A:$A,0) -> 0 | C114: Mr. VICTOR KIPNGETICH | D114: Contingent Worker | E114: Airtel Kenya | F114: 44246 | G114: 216113 | H114: Wanjohi, Miss Catherine Wairimu | I114: a_victor.kipngetich@ke.airtel.com | J114: 254787638889 | K114: Offrole | L114: Fine Media Ltd
A115: 23119291 | B115: =_xlfn.XLOOKUP(A115,'[2]Crowdstrike report'!$S:$S,'[2]Crowdstrike report'!$A:$A,0) -> 0 | C115: Mr. ERIC OMAR | D115: Contingent Worker | E115: Airtel Kenya | F115: 44246 | G115: 402949 | H115: Karomo, Mr. Kennedy Kimani | I115: a_eric.omar@ke.airtel.com | J115: 254737286648 | K115: Offrole | L115: Fine Media Ltd
A116: 23119292 | B116: =_xlfn.XLOOKUP(A116,'[2]Crowdstrike report'!$S:$S,'[2]Crowdstrike report'!$A:$A,0) -> 0 | C116: Miss LYNNET SITUMA | D116: Contingent Worker | E116: Airtel Kenya | F116: 44246 | G116: 401210 | H116: Igoro, Miss Stella Njeri | I116: a_lynnet.situma@ke.airtel.com | J116: 254731490003 | K116: Offrole | L116: Fine Media Ltd
A117: 23119738 | B117: =_xlfn.XLOOKUP(A117,'[2]Crowdstrike report'!$S:$S,'[2]Crowdstrike report'!$A:$A,0) -> 0 | C117: Mr. Deepak S | D117: Contingent Worker | E117: Airtel Kenya | F117: 44257 | G117: 2395298 | H117: SINGH, Mr. DUSHYANT KUMAR | I117: deepak.k.s@nokia.com | J117: 919962573922 | K117: Contingent Worker | L117: Nokia
A118: 23119942 | B118: =_xlfn.XLOOKUP(A118,'[2]Crowdstrike report'!$S:$S,'[2]Crowdstrike report'!$A:$A,0) -> 0 | C118: Ms. Lucy Maina | D118: Contingent Worker | E118: Airtel Kenya | F118: 44264 | G118: 1300243 | H118: Muthoni, Mrs. Juliet | I118: a_lucy.maina@ke.airtel.com | J118: 254751771705 | K118: Offrole | L118: Sheer Logic Management Consultants
A119: 23119984 | B119: =_xlfn.XLOOKUP(A119,'[2]Crowdstrike report'!$S:$S,'[2]Crowdstrike report'!$A:$A,0) -> 0 | C119: Mr. REUBEN OSANO | D119: Contingent Worker | E119: Airtel Kenya | F119: 44265 | G119: 1303431 | H119: Abuga, Mr. Jared Masi | I119: reubenosano@broadcom.co.ke | J119: 254790505831 | K119: Contingent Worker | L119: Nokia
A120: 23120020 | B120: =_xlfn.XLOOKUP(A120,'[2]Crowdstrike report'!$S:$S,'[2]Crowdstrike report'!$A:$A,0) -> 0 | C120: Mr. RAKESH DUBEY | D120: Contingent Worker | E120: Airtel Kenya | F120: 44266 | G120: 1303431 | H120: Abuga, Mr. Jared Masi | I120: rakesh.dubey@innovis.in | J120: 254776533800 | K120: Contingent Worker | L120: Innovis - Nokia
... A150: 23123760 | B150: =_xlfn.XLOOKUP(A150,'[2]Crowdstrike report'!$S:$S,'[2]Crowdstrike report'!$A:$A,0) -> KE-23123760-WD | C150: Ms. Anna Kisoi | D150: Contingent Worker | E150: Airtel Kenya | F150: 44355 | G150: 1300243 | H150: Muthoni, Mrs. Juliet | I150: a_anna.kisoi@ke.airtel.com | J150: 254788581584 | K150: Offrole | L150: Sheer Logic Management Consultants
A151: 23123949 | B151: =_xlfn.XLOOKUP(A151,'[2]Crowdstrike report'!$S:$S,'[2]Crowdstrike report'!$A:$A,0) -> 0 | C151: Mr. KEVIN MURIGIA | D151: Contingent Worker | E151: Airtel Kenya | F151: 44358 | G151: 1300243 | H151: Muthoni, Mrs. Juliet | I151: a_kevin.murigia@ke.airtel.com | J151: 254788175901 | K151: Offrole | L151: Sheer Logic Management Consultants | M151: Driving License Number | N151: 123456
A152: 23124866 | B152: =_xlfn.XLOOKUP(A152,'[2]Crowdstrike report'!$S:$S,'[2]Crowdstrike report'!$A:$A,0) -> 0 | C152: Miss Salome Musyoka | D152: Contingent Worker | E152: Airtel Kenya | F152: 44364 | G152: 1303431 | H152: Abuga, Mr. Jared Masi | I152: a_Salome.Musyoka.ke.airtel.com | J152: 254797697855 | K152: Contingent Worker | L152: Egypro
A153: 23125028 | B153: =_xlfn.XLOOKUP(A153,'[2]Crowdstrike report'!$S:$S,'[2]Crowdstrike report'!$A:$A,0) -> 0 | C153: Ms. Monica Raj | D153: Contingent Worker | E153: Airtel Kenya | F153: 44368 | G153: 2395298 | H153: SINGH, Mr. DUSHYANT KUMAR | I153: monica.r.ext@nokia.com | J153: 917708336858 | K153: Contingent Worker | L153: Nokia
A154: 23125095 | B154: =_xlfn.XLOOKUP(A154,'[2]Crowdstrike report'!$S:$S,'[2]Crowdstrike report'!$A:$A,0) -> 0 | C154: Miss Brenda Onyango | D154: Contingent Worker | E154: Airtel Kenya | F154: 44369 | G154: 1303431 | H154: Abuga, Mr. Jared Masi | I154: a_brenda.onynago@ke.airtel.com | J154: 254793624153 | K154: IT Ops | L154: Egypro
A155: 23125152 | B155: =_xlfn.XLOOKUP(A155,'[2]Crowdstrike report'!$S:$S,'[2]Crowdstrike report'!$A:$A,0) -> KE-23125152-WD | C155: Ms. Sheila Ngota | D155: Contingent Worker | E155: Airtel Kenya | F155: 44370 | G155: 401066 | H155: Namayi, Miss Florence Akinyi | I155: a_sheila.ngota@ke.airtel.com | J155: 254753728511 | K155: Offrole | L155: Sheer Logic Management Consultants
A156: 23126031 | B156: =_xlfn.XLOOKUP(A156,'[2]Crowdstrike report'!$S:$S,'[2]Crowdstrike report'!$A:$A,0) -> 0 | C156: Mr. Robert Okomo | D156: Contingent Worker | E156: Airtel Kenya | F156: 44382 | G156: 405416 | H156: Wanjohi, Ms. Sharon Wanja | I156: a_robert.Okomo@ke.airtel.com | J156: 254786363468 | K156: Offrole | L156: Sheer Logic Management Consultants
A157: 23126043 | B157: =_xlfn.XLOOKUP(A157,'[2]Crowdstrike report'!$S:$S,'[2]Crowdstrike report'!$A:$A,0) -> KE-23126043-WL | C157: Mr. Sammy Ebusuru | D157: Contingent Worker | E157: Airtel Kenya | F157: 44382 | G157: 1304315 | H157: Nyakanini, Ms. Purity Nyatana | I157: a_sammy1.ebusuru@ke.airtel.com | J157: 254789434995 | K157: Offrole | L157: Sheer Logic Management Consultants
A158: 23126407 | B158: =_xlfn.XLOOKUP(A158,'[2]Crowdstrike report'!$S:$S,'[2]Crowdstrike report'!$A:$A,0) -> 0 | C158: Mr. Joseph Muthoni | D158: Contingent Worker | E158: Airtel Kenya | F158: 44390 | G158: 1325076 | H158: Waweru, Mr. James Mwaniki | I158: a_joseph.muthoni@ke.airtel.com | J158: 254732717237 | K158: Offrole | L158: Sheer Logic Management Consultants
A159: 23126638 | B159: =_xlfn.XLOOKUP(A159,'[2]Crowdstrike report'!$S:$S,'[2]Crowdstrike report'!$A:$A,0) -> 0 | C159: Mr. Luke Mwema | D159: Contingent Worker | E159: Airtel Kenya | F159: 44396 | G159: 403481 | H159: Wanjohi, Mr. Robert James Kinga | I159: a_luke1.mwema@ke.airtel.com | J159: 254786409250 | K159: Offrole | L159: Sheer Logic Management Consultants
A160: 23126963 | B160: =_xlfn.XLOOKUP(A160,'[2]Crowdstrike report'!$S:$S,'[2]Crowdstrike report'!$A:$A,0) -> 0 | C160: Mr. Ubongabasi Samuel | D160: Contingent Worker | E160: Airtel Kenya | F160: 44400 | G160: 2357105 | H160: Dhananjay, Mr. Srivastava | I160: ubongabasi.samuel@isontechnologies.com | J160: 2348107548859 | K160: Call Center | L160: ISON
A161: 23127013 | B161: =_xlfn.XLOOKUP(A161,'[2]Crowdstrike report'!$S:$S,'[2]Crowdstrike report'!$A:$A,0) -> 0 | C161: Mr. Stanley Omambia | D161: Contingent Worker | E161: Airtel Kenya | F161: 44404 | G161: 401802 | H161: Isagi, Mr. Anthony Lubanga | I161: a_stanley.omambia@ke.airtel.com | J161: 254762971748 | K161: Offrole | L161: Sheer Logic Management Consultants
A162: 23127014 | B162: =_xlfn.XLOOKUP(A162,'[2]Crowdstrike report'!$S:$S,'[2]Crowdstrike report'!$A:$A,0) -> 0 | C162: Mr. Dominic Kipkoech | D162: Contingent Worker | E162: Airtel Kenya | F162: 44404 | G162: 211692 | H162: Magada, Mr. Gadin | I162: a_dominic.kipkoech@ke.airtel.com | J162: 254784919010 | K162: Offrole | L162: Sheer Logic Management Consultants
...

Sheet Sorted
A1: Associate Number | B1: Full Name | C1: Serial Number
A2: 2300031 | B2: Mr. Habert KHISA | C2: =VLOOKUP(A2,'Rough Work'!D2:D22775,4,TRUE) -> #REF!
A3: 2300032 | B3: Mr. Peter MWILU | C3: =VLOOKUP(A3,'Rough Work'!D2:D22776,4,TRUE) -> #REF!
A4: 2300034 | B4: Jeniffer MUHORO | C4: =VLOOKUP(A4,'Rough Work'!D2:D22777,4,TRUE) -> #REF!
A5: 2300117 | B5: Christine Ogalo | C5: =VLOOKUP(A5,'Rough Work'!D2:D22778,4,TRUE) -> #REF!
A6: 2304321 | B6: Mr. SAMUEL MATHEKA | C6: =VLOOKUP(A6,'Rough Work'!D2:D22779,4,TRUE) -> #REF!
A7: 2304952 | B7: Mr. Moses Mburu | C7: =VLOOKUP(A7,'Rough Work'!D3:D22780,4,TRUE) -> #REF!
A8: 23100021 | B8: Ms. Jane Kariuki | C8: =VLOOKUP(A8,'Rough Work'!D4:D22781,4,TRUE) -> #REF!
A9: 23100159 | B9: Mr. Geofrey Otieno | C9: =VLOOKUP(A9,'Rough Work'!D5:D22782,4,TRUE) -> #REF!
A10: 23100661 | B10: Mr. BONFACE OUMA | C10: =VLOOKUP(A10,'Rough Work'!D6:D22783,4,TRUE) -> #REF!
A11: 23100662 | B11: Mr. WALTER KADURENGE | C11: =VLOOKUP(A11,'Rough Work'!D7:D22784,4,TRUE) -> #REF!
A12: 23101437 | B12: Mr. Sanjeevkumar Shanmugavadivel | C12: =VLOOKUP(A12,'Rough Work'!D8:D22785,4,TRUE) -> #REF!
A13: 23101443 | B13: Mr. Srinivasan Natarajan | C13: =VLOOKUP(A13,'Rough Work'!D9:D22786,4,TRUE) -> #REF!
A14: 23101810 | B14: Ms. Kendi Njeru | C14: =VLOOKUP(A14,'Rough Work'!D10:D22787,4,TRUE) -> #REF!
A15: 23101930 | B15: Mr. EDWIN OKWARO | C15: =VLOOKUP(A15,'Rough Work'!D11:D22788,4,TRUE) -> #REF!
A16: 23101931 | B16: Mr. THOMAS ONYANCHA | C16: =VLOOKUP(A16,'Rough Work'!D12:D22789,4,TRUE) -> #REF!
A17: 23101932 | B17: Mr. DANIEL MWAI | C17: =VLOOKUP(A17,'Rough Work'!D13:D22790,4,TRUE) -> #REF!
... A6032: 2398814 | B6032: Mr. Pawel Gaworek | C6032: =VLOOKUP(A6032,'Rough Work'!D6028:D28805,4,TRUE) -> #REF!

Sheet Rough Work
A1: Hostname | B1: Model | C1: Manufacturer | D1: Serial Number
A2: 1123323D | B2: HP Pro 3500 Series | C2: Hewlett-Packard | D2: CZC2240HQD
A3: 121L1 | B3: HP ProBook 4340s | C3: Hewlett-Packard | D3: 2CE3030RML
A4: 13000062L2 | B4: HP Laptop 15-da1xxx | C4: HP | D4: CND9463BBD
A5: 1300009LL | B5: 21E6008CGR | C5: LENOVO | D5: PF48RB3Z
A6: 1300011L1 | B6: 20UASDMD00 | C6: LENOVO | D6: PF34XFAM
A7: 1300031L1 | B7: 21FHS8A800 | C7: LENOVO | D7: PW0A7H3P
A8: 1300032L | B8: 21JK00K4UE | C8: LENOVO | D8: PF4WB80N
A9: 1300032L | B9: 20NSS11W00 | C9: LENOVO | D9: R90VL4HE
A10: 1300036LL | B10: HP Laptop 15-dy2xxx | C10: HP | D10: 5CD1420BZ8
A11: 1300038L3 | B11: HP ProBook 440 G8 Notebook PC | C11: HP | D11: 5CD202653Q
A12: 1300043L | B12: HP EliteBook 630 13 inch G9 Notebook PC | C12: HP | D12: 5CD229BMY3
... A328: 1301408L1 | B328: 20NSS20D00 | C328: LENOVO | D328: R90VT6K1
A329: 1301429D | C329: Hewlett-Packard
A330: 1301429-G-MWD | C330: Hewlett-Packard
A331: 1301444L1 | B331: 20R4S39200 | C331: LENOVO | D331: R910WYQM
A332: 1301453D1 | B332: Vostro 3671 | C332: Dell Inc. | D332: D5B6933
A333: 1301453D2 | B333: Vostro 3671 | C333: Dell Inc. | D333: 85B6933
A334: 1301453L1 | B334: 21AJS7XX00 | C334: LENOVO | D334: PF4378MS
A335: 1301455L1 | B335: HP ProBook 440 G6 | C335: HP | D335: 5CD9501XFV
A336: 1301463L | B336: HP Laptop 14-dq2xxx | C336: HP | D336: 5CD0496061
A337: 1301475L2 | B337: HP ProBook 440 14 inch G9 Notebook PC | C337: HP | D337: 5CD318203B
A338: 1301482L | B338: 21JKS14D00 | C338: LENOVO | D338: PG04DZG3
A339: 1301482L1 | B339: 20S00012UE | C339: LENOVO | D339: PF2T0J8V
A340: 1301482L1 | B340: 21JKS14D00 | C340: LENOVO | D340: PG04DZG3
A341: 1301484L | B341: 21HES1Y000 | C341: LENOVO | D341: PF4DXLKB
A342: 1301490L | B342: 20M6S26700 | C342: LENOVO | D342: R90T6EVL
... A793: 1303692L | B793: HP ProBook 430 G6 | C793: HP | D793: 5CD943497S
A794: 1303713D10 | C794: HP
A795: 1303713D11A | B795: HP 200 G3 AiO | C795: HP | D795: 8CC83917DG
A796: 1303713D120 | B796: HP 200 G4 22 All-in-One PC | C796: HP | D796: 8CC0180RJY
A797: 1303713D121 | B797: HP 200 G4 22 All-in-One PC | C797: HP | D797: 8CC0180RMS
A798: 1303713D122 | B798: HP 200 G4 22 All-in-One PC | C798: HP | D798: 8CC1412SHR
A799: 1303713D123 | B799: HP 200 G4 22 All-in-One PC | C799: HP | D799: 8CC0180RMT
A800: 1303713D124 | B800: HP 200 G4 22 All-in-One PC | C800: HP | D800: 8CC0180RN9
A801: 1303713D126A | B801: HP 200 G4 22 All-in-One PC | C801: HP | D801: 8CC0180RMZ
A802: 1303713D127 | B802: HP 200 G4 22 All-in-One PC | C802: HP | D802: 8CC0180RM5
A803: 1303713D128A | B803: HP AiO 22 | C803: HP | D803: 8CC0180RM6
A804: 1303713D129 | B804: HP 200 G4 22 All-in-One PC | C804: HP | D804: 8CC0180RMR
A805: 1303713D130 | B805: HP 200 G4 22 All-in-One PC | C805: HP | D805: 8CC0180RLN
...

Sheet Sheet4
